package co.g3a.functionalrop.core;

import org.junit.jupiter.api.DisplayName;
import org.junit.jupiter.api.Test;

import java.util.concurrent.CompletionStage;
import java.util.concurrent.Executor;
import java.util.concurrent.Executors;

import static org.junit.jupiter.api.Assertions.*;

/**
 * Demuestra que DeadEnd puede funcionar sin ning√∫n tipo de error de dominio como AppError
 * utilizando simplemente Result<String, String>.
 */
public class DeadEndStringGenericTest {

    private final DeadEnd deadEnd;

    DeadEndStringGenericTest(){
        Executor executor = Executors.newVirtualThreadPerTaskExecutor();//O usa Runnable::run para ejecuci√≥n sincr√≥nica.
        this.deadEnd = new DeadEnd(executor);

    }

    @Test
    @DisplayName("üü¢ runSafe - √©xito con Result<String, String>")
    void runSafe_success_withStringError() {
        String input = "input correcto";

        CompletionStage<Result<String, String>> future = deadEnd.runSafeResultTransform(
                input,
                function -> {
                    System.out.println("üôÇ Procesando: " + input);
                    return Result.success(input);
                },
                ex -> "‚ùå Error capturado: " + ex.getMessage()
        );

        Result<String, String> result = future.toCompletableFuture().join();

        assertTrue(result.isSuccess());
        assertEquals(input, result.getValue());
    }

    @Test
    @DisplayName("üî¥ runSafe - falla con error mapeado (String)")
    void runSafe_failure_withStringError() {
        CompletionStage<Result<String, String>> future = deadEnd.runSafeResultTransform(
                "valor de entrada",
                function -> { throw new RuntimeException("üî® Error interno"); },
                ex -> "‚ùå Error simple: " + ex.getMessage()
        );

        Exception exception = assertThrows(RuntimeException.class, () -> {
            future.toCompletableFuture().join();
        });

        String expectedMessage = "‚ùå Error simple: üî® Error interno";
        String actualMessage = exception.getMessage();
        assertTrue(actualMessage.contains(expectedMessage));
    }

    @Test
    @DisplayName("üü¢ runSafeTransform - √©xito con String -> String")
    void runSafeResultTransform_success_withStringError() {
        CompletionStage<Result<String, String>> future = deadEnd.runSafeResultTransform(
                100,
                value -> Result.success("Resultado: " + (value + 1)),
                ex -> "‚ùå Error transformando: " + ex.getMessage()
        );

        Result<String, String> result = future.toCompletableFuture().join();

        assertTrue(result.isSuccess());
        assertEquals("Resultado: 101", result.getValue());
    }

    @Test
    @DisplayName("üî¥ runSafeTransform - con error de negocio")
    void runSafeResultTransform_failure_withStringError() {
        CompletionStage<Result<String, String>> future = deadEnd.runSafeResultTransform(
                "entrada",
                val -> {
                    return Result.failure("‚ö†Ô∏è No se puede procesar");
                },
                ex -> "‚ùå Error transformado: " + ex.getMessage()
        );

        Result<String, String> result = future.toCompletableFuture().join();

        assertFalse(result.isSuccess());
        assertTrue(result.getError().startsWith("‚ö†Ô∏è No se puede procesar"));

    }

    @Test
    @DisplayName("üî¥ runSafeTransform - con excepci√≥n transformada a String")
    void runSafeResultTransform_exception_withStringError() {
        CompletionStage<Result<String, String>> future = deadEnd.runSafeResultTransform(
                "entrada",
                val -> {
                    throw new RuntimeException("‚ö†Ô∏è No se puede procesar");
                },
                ex -> "‚ùå Error transformado: " + ex.getMessage()
        );
        Exception exception = assertThrows(RuntimeException.class, () -> {
            future.toCompletableFuture().join();
        });

        String expectedMessage = "‚ùå Error transformado: ‚ö†Ô∏è No se puede procesar";
        String actualMessage = exception.getMessage();

        assertTrue(actualMessage.contains(expectedMessage));



    }
}